Traceback (most recent call last):
  File "/usr/lib/python3/dist-packages/serial/serialposix.py", line 265, in open
    self.fd = os.open(self.portstr, os.O_RDWR | os.O_NOCTTY | os.O_NONBLOCK)
FileNotFoundError: [Errno 2] No such file or directory: '/dev/rfcomm0'

During handling of the above exception, another exception occurred:

Traceback (most recent call last):
  File "/home/pi/dcon/loop-main.py", line 61, in <module>
    s = serial.Serial('/dev/rfcomm0', 9600)
  File "/usr/lib/python3/dist-packages/serial/serialutil.py", line 240, in __init__
    self.open()
  File "/usr/lib/python3/dist-packages/serial/serialposix.py", line 268, in open
    raise SerialException(msg.errno, "could not open port {}: {}".format(self._port, msg))
serial.serialutil.SerialException: [Errno 2] could not open port /dev/rfcomm0: [Errno 2] No such file or directory: '/dev/rfcomm0'
